<?xml version="1.0" encoding="utf-8"?>
<!-- This URDF was automatically created by SolidWorks to URDF Exporter! Originally created by Stephen Brawner (brawner@gmail.com) 
     Commit Version: 1.6.0-1-g15f4949  Build Version: 1.6.7594.29634
     For more information, please see http://wiki.ros.org/sw_urdf_exporter -->
<robot
  name="robotv3">
  <link
    name="base_link">
    <inertial>
      <origin
        xyz="0 0 0"
        rpy="0 0 0" />
      <mass
        value="1.4249" />
      <inertia
        ixx="0.0031413"
        ixy="-4.3508E-09"
        ixz="-8.3589E-08"
        iyy="0.0063902"
        iyz="-1.8491E-05"
        izz="0.0037714" />
    </inertial>
    <visual>
      <origin
        xyz="0 0 0"
        rpy="0 0 0" />
      <geometry>
        <mesh
          filename="package://robotv3/meshes/base_link.STL" />
      </geometry>
      <material
        name="">
        <color
          rgba="1 1 1 1" />
      </material>
    </visual>
    <collision>
      <origin
        xyz="0 0 0"
        rpy="0 0 0" />
      <geometry>
        <mesh
          filename="package://robotv3/meshes/base_link.STL" />
      </geometry>
    </collision>
  </link>

  
  <link
    name="RuedaIzquiera_Link">
    <inertial>
      <origin
        xyz="0 0 0"
        rpy="0 0 0" />
      <mass
        value="0.051174" />
      <inertia
        ixx="2.6466E-05"
        ixy="-2.103E-10"
        ixz="-1.8221E-12"
        iyy="2.6484E-05"
        iyz="-5.8818E-12"
        izz="5.2091E-05" />
    </inertial>
    <visual>
      <origin
        xyz="0 0 0"
        rpy="0 0 0" />
      <geometry>
        <mesh
          filename="package://robotv3/meshes/RuedaIzquiera_Link.STL" />
      </geometry>
      <material
        name="">
        <color
          rgba="0.79216 0.81961 0.93333 1" />
      </material>
    </visual>
    <collision>
      <origin
        xyz="0 0 0"
        rpy="0 0 0" />
      <geometry>
        <mesh
          filename="package://robotv3/meshes/RuedaIzquiera_Link.STL" />
      </geometry>
    </collision>
  </link>


  <joint
    name="RuedaIzquiera_Join"
    type="continuous">
    <origin
      xyz="0.077499 -0.046747 0.0188"
      rpy="1.5708 0.31998 1.5708" />
    <parent
      link="base_link" />
    <child
      link="RuedaIzquiera_Link" />
    <axis
      xyz="0 0 1" />
  </joint>



  <link
    name="RuedaDerecha_Link">
    <inertial>
      <origin
        xyz="0 0 0"
        rpy="0 0 0" />
      <mass
        value="0.051174" />
      <inertia
        ixx="2.6466E-05"
        ixy="-2.1296E-10"
        ixz="-1.7932E-12"
        iyy="2.6484E-05"
        iyz="-6.071E-12"
        izz="5.2091E-05" />
    </inertial>
    <visual>
      <origin
        xyz="0 0 0"
        rpy="0 0 0" />
      <geometry>
        <mesh
          filename="package://robotv3/meshes/RuedaDerecha_Link.dae" />
      </geometry>
      <material
        name="">
        <color
          rgba="0.79216 0.81961 0.93333 1" />
      </material>
    </visual>
    <collision>
      <origin
        xyz="0 0 0"
        rpy="0 0 0" />
      <geometry>
        <mesh
          filename="package://robotv3/meshes/RuedaDerecha_Link.dae" />
      </geometry>
    </collision>
  </link>
  <joint
    name="RuedaDerecha_Join"
    type="continuous">
    <origin
      xyz="-0.077499 -0.046668 0.0188"
      rpy="1.5708 -0.6635 1.5708" />
    <parent
      link="base_link" />
    <child
      link="RuedaDerecha_Link" />
    <axis
      xyz="0 0 1" />
  </joint>





  <link
    name="Camara_Link">
    <inertial>
      <origin
        xyz="0 0 0"
        rpy="0 0 0" />
      <mass
        value="0.021409" />
      <inertia
        ixx="8.5599E-06"
        ixy="-1.5783E-21"
        ixz="-2.1926E-09"
        iyy="9.5278E-06"
        iyz="-1.0965E-06"
        izz="8.6521E-06" />
    </inertial>
    <visual>
      <origin
        xyz="0 0 0"
        rpy="0 0 0" />
      <geometry>
        <mesh
          filename="package://robotv3/meshes/Camara_Link.STL" />
      </geometry>
      <material
        name="">
        <color
          rgba="0.96471 0.96471 0.95294 1" />
      </material>
    </visual>
    <collision>
      <origin
        xyz="0 0 0"
        rpy="0 0 0" />
      <geometry>
        <mesh
          filename="package://robotv3/meshes/Camara_Link.STL" />
      </geometry>
    </collision>
  </link>

  <joint
    name="Camara_Join"
    type="fixed">
    <origin
      xyz="0.0023614 -0.099152 0.1263"
      rpy="1.5708 0 0.023812" />
    <parent
      link="base_link" />
    <child
      link="Camara_Link" />
    <axis
      xyz="0 0 0" />
  </joint>

  <link
    name="Lidar_Link">
    <inertial>
      <origin
        xyz="0 0 0"
        rpy="0 0 0" />
      <mass
        value="0" />
      <inertia
        ixx="0.00058388"
        ixy="0.00015345"
        ixz="8.9875E-07"
        iyy="0.0010719"
        iyz="3.0431E-06"
        izz="0.00091993" />
    </inertial>
    <visual>
      <origin
        xyz="0 0 0"
        rpy="0 0 0" />
      <geometry>
        <mesh
          filename="package://robotv3/meshes/Lidar_Link.STL" />
      </geometry>
      <material
        name="">
        <color
          rgba="0.79216 0.81961 0.93333 1" />
      </material>
    </visual>
    <collision>
      <origin
        xyz="0 0 0"
        rpy="0 0 0" />
      <geometry>
        <mesh
          filename="package://robotv3/meshes/Lidar_Link.STL" />
      </geometry>
    </collision>
  </link>

  <joint
    name="Lider_Join"
    type="fixed">
    <origin
      xyz="0 -0.07775 0.2396"
      rpy="0 0 -1.5708" />
    <parent
      link="base_link" />
    <child
      link="Lidar_Link" />
    <axis
      xyz="0 0 0" />
  </joint>
    <!--              GAZEBO PLUGINS                     -->


  <!--                    differential_drive_controller               -->
  <gazebo>
    <plugin filename="libgazebo_ros_diff_drive.so" name="differential_drive_controller">
      <leftJoint>RuedaIzquiera_Join</leftJoint>
      <legacyMode>false</legacyMode>
      <rightJoint>RuedaDerecha_Join</rightJoint>

      <robotBaseFrame>base_link</robotBaseFrame>
      <wheelSeperation>0.235</wheelSeperation>
      <wheelDiameter>0.090</wheelDiameter>
      <publishWheelJointState>true</publishWheelJointState>
    </plugin>
  </gazebo>
    <!--                    lidar               -->
  <gazebo reference="Lidar_Link">
      <sensor type="ray" name="head_hokuyo_sensor">
        <pose>0 0 0 0 0 0</pose>
        <visualize>true</visualize>
        <update_rate>4</update_rate>
        <ray>
          <scan>
            <horizontal>
              <samples>720</samples>
              <resolution>1</resolution>
              <min_angle>-1.570796</min_angle>
              <max_angle>1.570796</max_angle>
            </horizontal>
          </scan>
          <range>
            <min>0.10</min>
            <max>6.0</max>
            <resolution>0.01</resolution>
          </range>
          <noise>
            <type>gaussian</type>
            <!--Noise parameters based on published spec for Hokuyo laser
                achieving "+-30mm" accuracy at range < 10m.  A mean of 0.0m and
                stddev of 0.01m will put 99.7% of samples within 0.03m of the true
                reading. -->
            <mean>0.0</mean>
            <stddev>0.01</stddev>
          </noise>
        </ray>
        <plugin name="gazebo_ros_head_hokuyo_controller" filename="libgazebo_ros_laser.so">
          <topicName>/laser/scan</topicName>
          <frameName>Lidar_Link</frameName>
        </plugin>
      </sensor>
    </gazebo>
    
    <!-- camera -->
    <gazebo reference="Camara_Link">
      <sensor type="camera" name="camera1">
        <update_rate>30.0</update_rate>
        <camera name="head">
          <pose>-0.2 0 0 -1.5708 -1.5708 0</pose>
          <horizontal_fov>1.3962634</horizontal_fov>
          <image>
            <width>800</width>
            <height>800</height>
            <format>R8G8B8</format>
          </image>
          <clip>
            <near>0.02</near>
            <far>300</far>
          </clip>
          <noise>
            <type>gaussian</type>
            <!-- Noise is sampled independently per pixel on each frame.
                That pixel's noise value is added to each of its color
                channels, which at that point lie in the range [0,1]. -->
            <mean>0.0</mean>
            <stddev>0.007</stddev>
          </noise>
        </camera>
        <plugin name="camera_controller" filename="libgazebo_ros_camera.so">
          <alwaysOn>true</alwaysOn>
          <updateRate>0.0</updateRate>
          <cameraName>robot_v3/camera1</cameraName>
          <imageTopicName>image_raw</imageTopicName>
          <cameraInfoTopicName>camera_info</cameraInfoTopicName>
          <frameName>Camara_Link</frameName>
          <hackBaseline>0.07</hackBaseline>
          <distortionK1>0.0</distortionK1>
          <distortionK2>0.0</distortionK2>
          <distortionK3>0.0</distortionK3>
          <distortionT1>0.0</distortionT1>
          <distortionT2>0.0</distortionT2>
        </plugin>
      </sensor>
    </gazebo>
</robot>